ERROR:grpc._cython.cygrpc:Unexpected [AttributeError] raised by servicer method [/object_storage.ObjectStorageService/ListObjects]
Traceback (most recent call last):
  File "src\python\grpcio\grpc\_cython\_cygrpc/aio/server.pyx.pxi", line 682, in grpc._cython.cygrpc._handle_exceptions
  File "src\python\grpcio\grpc\_cython\_cygrpc/aio/server.pyx.pxi", line 802, in _handle_rpc
  File "src\python\grpcio\grpc\_cython\_cygrpc/aio/server.pyx.pxi", line 547, in _handle_unary_unary_rpc
  File "src\python\grpcio\grpc\_cython\_cygrpc/aio/server.pyx.pxi", line 404, in _finish_handler_with_unary_response
  File "D:\Projects\ObjDirectory\src\grps_server.py", line 24, in wrapper
    context.user_id = payload['user_id']
AttributeError: 'grpc._cython.cygrpc._ServicerContext' object has no attribute 'user_id'
ERROR:grpc._cython.cygrpc:Unexpected [TypeError] raised by servicer method [/object_storage.ObjectStorageService/Authenticate]
Traceback (most recent call last):
  File "src\python\grpcio\grpc\_cython\_cygrpc/aio/server.pyx.pxi", line 682, in grpc._cython.cygrpc._handle_exceptions
  File "src\python\grpcio\grpc\_cython\_cygrpc/aio/server.pyx.pxi", line 802, in _handle_rpc
  File "src\python\grpcio\grpc\_cython\_cygrpc/aio/server.pyx.pxi", line 547, in _handle_unary_unary_rpc
  File "src\python\grpcio\grpc\_cython\_cygrpc/aio/server.pyx.pxi", line 404, in _finish_handler_with_unary_response
  File "D:\Projects\ObjDirectory\src\grps_server.py", line 46, in Authenticate
    user = await authenticate_user(request.username, request.password)
TypeError: object dict can't be used in 'await' expression
ERROR:grpc._cython.cygrpc:Unexpected [TypeError] raised by servicer method [/object_storage.ObjectStorageService/Authenticate]
Traceback (most recent call last):
  File "src\python\grpcio\grpc\_cython\_cygrpc/aio/server.pyx.pxi", line 682, in grpc._cython.cygrpc._handle_exceptions
  File "src\python\grpcio\grpc\_cython\_cygrpc/aio/server.pyx.pxi", line 802, in _handle_rpc
  File "src\python\grpcio\grpc\_cython\_cygrpc/aio/server.pyx.pxi", line 547, in _handle_unary_unary_rpc
  File "src\python\grpcio\grpc\_cython\_cygrpc/aio/server.pyx.pxi", line 404, in _finish_handler_with_unary_response
  File "D:\Projects\ObjDirectory\src\grps_server.py", line 46, in Authenticate
    user = await authenticate_user(request.username, request.password)
TypeError: object dict can't be used in 'await' expression
ERROR:grpc._cython.cygrpc:Unexpected [TypeError] raised by servicer method [/object_storage.ObjectStorageService/Authenticate]
Traceback (most recent call last):
  File "src\python\grpcio\grpc\_cython\_cygrpc/aio/server.pyx.pxi", line 682, in grpc._cython.cygrpc._handle_exceptions
  File "src\python\grpcio\grpc\_cython\_cygrpc/aio/server.pyx.pxi", line 802, in _handle_rpc
  File "src\python\grpcio\grpc\_cython\_cygrpc/aio/server.pyx.pxi", line 547, in _handle_unary_unary_rpc
  File "src\python\grpcio\grpc\_cython\_cygrpc/aio/server.pyx.pxi", line 404, in _finish_handler_with_unary_response
  File "D:\Projects\ObjDirectory\src\grps_server.py", line 46, in Authenticate
    user = await authenticate_user(request.username, request.password)
TypeError: object dict can't be used in 'await' expression
ERROR:grpc._server:Exception calling application: server closed the connection unexpectedly
	This probably means the server terminated abnormally
	before or while processing the request.
server closed the connection unexpectedly
	This probably means the server terminated abnormally
	before or while processing the request.
Traceback (most recent call last):
  File "C:\Users\mrtak\Miniconda3\envs\objtest\lib\site-packages\grpc\_server.py", line 552, in _call_behavior
    response_or_iterator = behavior(argument, context)
  File "D:\Projects\ObjDirectory\src\grps_server.py", line 45, in Authenticate
    user = user_manager.authenticate_user(request.username, request.password)
  File "D:\Projects\ObjDirectory\src\auth\user_manager.py", line 19, in authenticate_user
    cur.execute("SELECT * FROM users WHERE username = %s", (username,))
  File "C:\Users\mrtak\Miniconda3\envs\objtest\lib\site-packages\psycopg2\extras.py", line 236, in execute
    return super().execute(query, vars)
psycopg2.OperationalError: server closed the connection unexpectedly
	This probably means the server terminated abnormally
	before or while processing the request.
server closed the connection unexpectedly
	This probably means the server terminated abnormally
	before or while processing the request.

ERROR:grpc._common:Exception serializing message!
Traceback (most recent call last):
  File "C:\Users\mrtak\Miniconda3\envs\objtest\lib\site-packages\grpc\_common.py", line 89, in _transform
    return transformer(message)
TypeError: descriptor 'SerializeToString' for 'google._upb._message.Message' objects doesn't apply to a 'int' object
ERROR:grpc._common:Exception serializing message!
Traceback (most recent call last):
  File "C:\Users\mrtak\Miniconda3\envs\objtest\lib\site-packages\grpc\_common.py", line 89, in _transform
    return transformer(message)
TypeError: descriptor 'SerializeToString' for 'google._upb._message.Message' objects doesn't apply to a 'int' object
ERROR:grpc._common:Exception serializing message!
Traceback (most recent call last):
  File "C:\Users\mrtak\Miniconda3\envs\objtest\lib\site-packages\grpc\_common.py", line 89, in _transform
    return transformer(message)
TypeError: descriptor 'SerializeToString' for 'google._upb._message.Message' objects doesn't apply to a 'int' object
ERROR:grpc._server:Exception calling application: dump() missing 1 required positional argument: 'fp'
Traceback (most recent call last):
  File "D:\Projects\ObjDirectory\src\grps_server.py", line 70, in UploadObject
    metadata=self._metadata_to_proto(storage_object.metadata)
  File "D:\Projects\ObjDirectory\src\grps_server.py", line 150, in _metadata_to_proto
    return object_storage_pb2.ObjectMetadata(
TypeError: bad argument type for built-in operation

During handling of the above exception, another exception occurred:

Traceback (most recent call last):
  File "C:\Users\mrtak\Miniconda3\envs\objtest\lib\site-packages\grpc\_server.py", line 552, in _call_behavior
    response_or_iterator = behavior(argument, context)
  File "D:\Projects\ObjDirectory\src\grps_server.py", line 30, in wrapper
    return func(self, request, context)
  File "D:\Projects\ObjDirectory\src\grps_server.py", line 73, in UploadObject
    context.abort(grpc.StatusCode.INTERNAL, json.dump(e.__traceback__))
TypeError: dump() missing 1 required positional argument: 'fp'
ERROR:grpc._server:Exception calling application: Object of type traceback is not JSON serializable
Traceback (most recent call last):
  File "D:\Projects\ObjDirectory\src\grps_server.py", line 70, in UploadObject
    metadata=self._metadata_to_proto(storage_object.metadata)
  File "D:\Projects\ObjDirectory\src\grps_server.py", line 150, in _metadata_to_proto
    return object_storage_pb2.ObjectMetadata(
TypeError: bad argument type for built-in operation

During handling of the above exception, another exception occurred:

Traceback (most recent call last):
  File "C:\Users\mrtak\Miniconda3\envs\objtest\lib\site-packages\grpc\_server.py", line 552, in _call_behavior
    response_or_iterator = behavior(argument, context)
  File "D:\Projects\ObjDirectory\src\grps_server.py", line 30, in wrapper
    return func(self, request, context)
  File "D:\Projects\ObjDirectory\src\grps_server.py", line 73, in UploadObject
    context.abort(grpc.StatusCode.INTERNAL, json.dumps(e.__traceback__))
  File "C:\Users\mrtak\Miniconda3\envs\objtest\lib\json\__init__.py", line 231, in dumps
    return _default_encoder.encode(obj)
  File "C:\Users\mrtak\Miniconda3\envs\objtest\lib\json\encoder.py", line 199, in encode
    chunks = self.iterencode(o, _one_shot=True)
  File "C:\Users\mrtak\Miniconda3\envs\objtest\lib\json\encoder.py", line 257, in iterencode
    return _iterencode(o, 0)
  File "C:\Users\mrtak\Miniconda3\envs\objtest\lib\json\encoder.py", line 179, in default
    raise TypeError(f'Object of type {o.__class__.__name__} '
TypeError: Object of type traceback is not JSON serializable
